{"status":"TESTS_FAILED","testResults":[{"name":"test.test_triple_square.TripleSquare.test_calls","successful":false,"message":"7 not found in [4, 10] : Are you sure you called \u0027triple\u0027 the right number of times?","valgrindFailed":false,"points":["p01-06.1"],"exception":["  File \"/home/nikolai/anaconda3/lib/python3.7/unittest/case.py\", line 59, in testPartExecutor\n    yield\n","  File \"/home/nikolai/anaconda3/lib/python3.7/unittest/case.py\", line 628, in run\n    testMethod()\n","  File \"/home/nikolai/Documents/learning/datascience_mooc/exercises/tmcdata/TMC workspace/Exercises/hy/hy-data-analysis-with-python-2020/part01-e06_triple_square/test/test_triple_square.py\", line 63, in test_calls\n    self.call_helper([4, 10])\n","  File \"/home/nikolai/Documents/learning/datascience_mooc/exercises/tmcdata/TMC workspace/Exercises/hy/hy-data-analysis-with-python-2020/part01-e06_triple_square/test/test_triple_square.py\", line 43, in call_helper\n    msg\u003d\"Are you sure you called \u0027triple\u0027 the right number of times?\")\n","  File \"/home/nikolai/anaconda3/lib/python3.7/unittest/case.py\", line 1119, in assertIn\n    self.fail(self._formatMessage(msg, standardMsg))\n","  File \"/home/nikolai/anaconda3/lib/python3.7/unittest/case.py\", line 693, in fail\n    raise self.failureException(msg)\n"]},{"name":"test.test_triple_square.TripleSquare.test_calls2","successful":false,"message":"7 not found in [4] : Are you sure you called \u0027triple\u0027 the right number of times?","valgrindFailed":false,"points":["p01-06.2"],"exception":["  File \"/home/nikolai/anaconda3/lib/python3.7/unittest/case.py\", line 59, in testPartExecutor\n    yield\n","  File \"/home/nikolai/anaconda3/lib/python3.7/unittest/case.py\", line 628, in run\n    testMethod()\n","  File \"/home/nikolai/Documents/learning/datascience_mooc/exercises/tmcdata/TMC workspace/Exercises/hy/hy-data-analysis-with-python-2020/part01-e06_triple_square/test/test_triple_square.py\", line 68, in test_calls2\n    self.call_helper([4])\n","  File \"/home/nikolai/Documents/learning/datascience_mooc/exercises/tmcdata/TMC workspace/Exercises/hy/hy-data-analysis-with-python-2020/part01-e06_triple_square/test/test_triple_square.py\", line 43, in call_helper\n    msg\u003d\"Are you sure you called \u0027triple\u0027 the right number of times?\")\n","  File \"/home/nikolai/anaconda3/lib/python3.7/unittest/case.py\", line 1119, in assertIn\n    self.fail(self._formatMessage(msg, standardMsg))\n","  File \"/home/nikolai/anaconda3/lib/python3.7/unittest/case.py\", line 693, in fail\n    raise self.failureException(msg)\n"]},{"name":"test.test_triple_square.TripleSquare.test_square_output_and_type","successful":true,"message":"","valgrindFailed":false,"points":["p01-06.1"],"exception":[]},{"name":"test.test_triple_square.TripleSquare.test_tiple_output_and_type","successful":true,"message":"","valgrindFailed":false,"points":["p01-06.1"],"exception":[]}],"logs":{}}